<robot name="arm08">
  <link name="base_footprint"></link>
  <joint name="base_joint" type="fixed">
    <parent link="base_footprint" />
    <child link="base_link" />
    <origin xyz="0 0 -0.01" rpy="0 0 0" />
  </joint>
  <link name="base_link">
    <visual>
      <origin xyz="0 0 0" rpy="0 0 0" />
      <geometry>
        <cylinder radius="0.0254" length="0.02" />
      </geometry>
      <material name="base_link-material">
        <color rgba="1 1 1 1" />
      </material>
    </visual>
    <collision>
      <origin xyz="0 0 0" rpy="0 0 0" />
      <geometry>
        <cylinder radius="0.0254" length="0.02" />
      </geometry>
    </collision>
    <inertial>
      <origin xyz="0 0 0" rpy="0 0 0" />
      <mass value="1" />
      <inertia ixx="0.3333333333333333" ixy="0" ixz="0" iyy="0.5" iyz="0" izz="0.3333333333333333" />
    </inertial>
  </link>
  <joint name="base_link_to_axis_0" type="revolute">
    <parent link="base_link" />
    <child link="axis_0" />
    <origin xyz="0 0 0.05" rpy="0 0 0" />
    <axis xyz="0 0 1"/>
    <limit effort="1000.0" lower="-6.28" upper="6.28" velocity="0.5"/>  </joint>
  <link name="axis_0">
    <visual>
      <origin xyz="0 0 0" rpy="0 0 0" />
      <geometry>
        <cylinder radius="0.0254" length="0.08382" />
      </geometry>
      <material name="axis_0-material">
        <color rgba="1 0 0 1" />
      </material>
    </visual>
    <collision>
      <origin xyz="0 0 0" rpy="0 0 0" />
      <geometry>
        <cylinder radius="0.0254" length="0.08382" />
      </geometry>
    </collision>
    <inertial>
      <origin xyz="0 0 0" rpy="0 0 0" />
      <mass value="1" />
      <inertia ixx="0.3333333333333333" ixy="0" ixz="0" iyy="0.5" iyz="0" izz="0.3333333333333333" />
    </inertial>
  </link>
  <joint name="axis_0_to_axis_1" type="revolute">
    <parent link="axis_0" />
    <child link="axis_1" />
    <origin xyz="0 3.061616997868383e-17 0.04471600148335175" rpy="3.141592653589793 0 0" />
    <axis xyz="0 0.9999988884298535 -0.0014910194691437617"/>
    <limit effort="1000.0" lower="-1" upper="1" velocity="0.5"/>  </joint>
  <link name="axis_1">
    <visual>
      <origin xyz="0 0 -0.25" rpy="0 0 0" />
      <geometry>
        <cylinder radius="0.0254" length="0.506" />
      </geometry>
      <material name="axis_1-material">
        <color rgba="1 1 1 1" />
      </material>
    </visual>
    <collision>
      <origin xyz="0 0 -0.25" rpy="0 0 0" />
      <geometry>
        <cylinder radius="0.0254" length="0.50597" />
      </geometry>
    </collision>
    <inertial>
      <origin xyz="0 0 -0.25" rpy="0 0 0" />
      <mass value="1" />
      <inertia ixx="0.3333333333333333" ixy="0" ixz="0" iyy="0.5" iyz="0" izz="0.3333333333333333" />
    </inertial>

        <sensor type="imu" name="imu">
            <always_on>true</always_on>
            <update_rate>100</update_rate>
            <origin>0 3.061616997868383e-17 0.04471600148335175 3.141592653589793 0 0</origin>
            <imu>
                <noise>
                    <type>gaussian</type>
                    <mean>0</mean>
                    <stddev>0</stddev>
                </noise>
            </imu>
        </sensor>
      </link>
  <joint name="axis_1_to_axis_2" type="revolute">
    <parent link="axis_1" />
    <child link="axis_2" />
    <origin xyz="0 6.153848323092027e-17 -0.5024998495383791" rpy="0 0 0" />
    <axis xyz="0 0.9999988884298535 -0.0014910194691437617"/>
    <limit effort="1000.0" lower="-1" upper="1" velocity="0.5"/>  </joint>
  <link name="axis_2">
    <visual>
      <origin xyz="0 0 -0.218" rpy="0 0 0" />
      <geometry>
        <cylinder radius="0.0254" length="0.435" />
      </geometry>
      <material name="axis_2-material">
        <color rgba="1 0 0 1" />
      </material>
    </visual>
    <collision>
      <origin xyz="0 0 -0.218" rpy="0 0 0" />
      <geometry>
        <cylinder radius="0.0254" length="0.435" />
      </geometry>
    </collision>
    <inertial>
      <origin xyz="0 0 -0.218" rpy="0 0 0" />
      <mass value="1" />
      <inertia ixx="0.3333333333333333" ixy="0" ixz="0" iyy="0.5" iyz="0" izz="0.3333333333333333" />
    </inertial>

        <sensor type="imu" name="imu">
            <always_on>true</always_on>
            <update_rate>100</update_rate>
            <origin>0 6.153848323092027e-17 -0.5024998495383791 0 0 0</origin>
            <imu>
                <noise>
                    <type>gaussian</type>
                    <mean>0</mean>
                    <stddev>0</stddev>
                </noise>
            </imu>
        </sensor>
      </link>
  <joint name="axis_2_to_axis_3" type="revolute">
    <parent link="axis_2" />
    <child link="axis_3" />
    <origin xyz="-1.3684555315672042e-48 5.328069018879327e-17 -0.43750015046162083" rpy="0 0 0" />
    <axis xyz="0 0.9999988884298535 -0.0014910194691437617"/>
    <limit effort="1000.0" lower="-1" upper="1" velocity="0.5"/>  </joint>
  <link name="axis_3">
    <visual>
      <origin xyz="0 0 -0.074" rpy="0 0 0" />
      <geometry>
        <cylinder radius="0.0254" length="0.147" />
      </geometry>
      <material name="axis_3-material">
        <color rgba="1 1 1 1" />
      </material>
    </visual>
    <collision>
      <origin xyz="0 0 -0.074" rpy="0 0 0" />
      <geometry>
        <cylinder radius="0.0254" length="0.147" />
      </geometry>
    </collision>
    <inertial>
      <origin xyz="0 0 -0.074" rpy="0 0 0" />
      <mass value="1" />
      <inertia ixx="0.3333333333333333" ixy="0" ixz="0" iyy="0.5" iyz="0" izz="0.3333333333333333" />
    </inertial>

        <sensor type="imu" name="imu">
            <always_on>true</always_on>
            <update_rate>100</update_rate>
            <origin>-1.3684555315672042e-48 5.328069018879327e-17 -0.43750015046162083 0 0 0</origin>
            <imu>
                <noise>
                    <type>gaussian</type>
                    <mean>0</mean>
                    <stddev>0</stddev>
                </noise>
            </imu>
        </sensor>
      </link>
  <joint name="axis_3_to_axis_4" type="revolute">
    <parent link="axis_3" />
    <child link="axis_4" />
    <origin xyz="-2.7369110631344083e-48 1.1287594929093411e-16 -0.197061665303075" rpy="-3.141592653589793 0 0" />
    <axis xyz="0.9999851189996602 -0.0027401621036693916 0.004717339385813105"/>
    <limit effort="1000.0" lower="-1" upper="1" velocity="0.5"/>  </joint>
  <link name="axis_4">
    <visual>
      <origin xyz="0 0 0" rpy="0 -1.5707963267948966 0" />
      <geometry>
        <cylinder radius="0.052" length="0.122" />
      </geometry>
      <material name="axis_4-material">
        <color rgba="0.7379104087672317 0.1912016827303171 0.09758734713304495 1" />
      </material>
    </visual>
    <collision>
      <origin xyz="0 0 0" rpy="0 -1.5707963267948966 0" />
      <geometry>
        <cylinder radius="0.052" length="0.122" />
      </geometry>
    </collision>
    <inertial>
      <origin xyz="0 0 0" rpy="0 0 0" />
      <mass value="1" />
      <inertia ixx="0.3333333333333333" ixy="0" ixz="0" iyy="0.5" iyz="0" izz="0.3333333333333333" />
    </inertial>
  </link>
  <joint name="axis_4_to_axis_5" type="revolute">
    <parent link="axis_4" />
    <child link="axis_5" />
    <origin xyz="4.1053665947016125e-48 5.782905984730683e-17 0.139447752922093" rpy="0 0 0" />
    <axis xyz="0 0 1"/>
    <limit effort="1000.0" lower="-6.28" upper="6.28" velocity="0.5"/>  </joint>
  <link name="axis_5">
    <visual>
      <origin xyz="0 0 0" rpy="0 0 0" />
      <geometry>
        <box size="0.05 0.15 0.17551" />
      </geometry>
      <material name="axis_5-material">
        <color rgba="0.08437621153575764 0.004024717016506897 0.13013647668074665 1" />
      </material>
    </visual>
    <collision>
      <origin xyz="0 0 0" rpy="0 0 0" />
      <geometry>
        <box size="0.05 0.15 0.17551" />
      </geometry>
    </collision>
    <inertial>
      <origin xyz="0 0 0" rpy="0 0 0" />
      <mass value="1" />
      <inertia ixx="0.16666666666666666" ixy="0" ixz="0" iyy="0.16666666666666666" iyz="0" izz="0.16666666666666666" />
    </inertial>
  </link>
</robot>